<?xml version="1.0"?>
<robot xmlns:xacro="http://ros.org/wiki/xacro">

    <xacro:macro name="wheel_right" params="gazebo">

        <link name="right_wheel_link">
            <inertial>
                <origin xyz="-5.21540644005114e-10 -0.007500001005828386 2.2351741638115818e-10"
                    rpy="0 0 0" />
                <mass value="0.2312015843501238" />
                <inertia ixx="4e-05" iyy="7.2e-05" izz="4e-05" ixy="0.0" iyz="-0.0" ixz="0.0" />
            </inertial>
            <visual>
                <origin xyz="0.035 0.0725 -0.025" rpy="0 0 0" />
                <geometry>
                    <mesh filename="package://tcebot_description/meshes/right_wheel.stl"
                        scale="0.001 0.001 0.001" />
                </geometry>
            </visual>
            <collision>
                <origin xyz="0.035 0.0725 -0.025" rpy="0 0 0" />
                <geometry>
                    <mesh filename="package://tcebot_description/meshes/right_wheel.stl"
                        scale="0.001 0.001 0.001" />
                </geometry>
            </collision>
        </link>

        <joint name="right_wheel_joint" type="continuous">
            <origin xyz="-0.035 -0.0725 0.025" rpy="0 0 0" />
            <parent link="base_link" />
            <child link="right_wheel_link" />
            <axis xyz="0.0 1.0 0.0" />
        </joint>

        <gazebo reference="right_wheel_link">
            <mu1>1.0</mu1>
            <mu2>1.0</mu2>
            <kp>1000000.0</kp>
            <kd>100.0</kd>
            <minDepth>0.0001</minDepth>
            <maxVel>1.0</maxVel>
            <material>Gazebo/DarkGrey</material>
        </gazebo>

    </xacro:macro>
</robot>